Workbook

Sheet students
A1: STT | B1: StudentID | C1: LopID | D1: HoSV | E1: TenSV | F1: Phai | G1: NgaySinh | H1: SoDienThoai | I1: CMND
A2: =ROW()-1 -> 1 | B2: 122000002 | C2: 22CT111 | D2: Nguyễn Hoàng | E2: Quốc | F2: Nam | G2: 37997 | H2: 939439479
A3: =ROW()-1 -> 2 | B3: 122000015 | C3: 22CT111 | D3: Mai Trung Hoài | E3: Phong | F3: Nam | G3: 16/10/2004 | H3: 824997687 | I3: 75204002778
A4: =ROW()-1 -> 3 | B4: 122000057 | C4: 22CT111 | D4: Diệp Thị Mỹ | E4: Hằng | F4: Nữ | G4: 19/12/2003 | H4: 937018921 | I4: 58303001234
A5: =ROW()-1 -> 4 | B5: 122000090 | C5: 22CT111 | D5: Nguyễn Trung | E5: Nghĩa | F5: Nam | G5: 23/11/2004 | H5: 839446137 | I5: 75204012276
A6: =ROW()-1 -> 5 | B6: 122000093 | C6: 22CT111 | D6: Trương Quốc | E6: Hòa | F6: Nam | G6: 28/08/2004 | H6: 778754895 | I6: 72204012261
A7: =ROW()-1 -> 6 | B7: 122000111 | C7: 22CT111 | D7: Phạm Anh | E7: Đức | F7: Nam | G7: 30/04/2004 | H7: 973894731 | I7: 75204012577
A8: =ROW()-1 -> 7 | B8: 122000209 | C8: 22CT111 | D8: Lê Tuấn | E8: Anh | F8: Nam | G8: 38049 | H8: 388169322 | I8: 54204009222
A9: =ROW()-1 -> 8 | B9: 122000224 | C9: 22CT111 | D9: Trương Nguyên | E9: Giáp | F9: Nam | G9: 38021 | H9: 368609650 | I9: 75204018457
A10: =ROW()-1 -> 9 | B10: 122000232 | C10: 22CT111 | D10: Hà Vũ | E10: Khải | F10: Nam | G10: 23/10/2004 | H10: 356813741 | I10: 75204021608
A11: =ROW()-1 -> 10 | B11: 122000246 | C11: 22CT111 | D11: Ngô Minh | E11: Quân | F11: Nam | G11: 19/11/2004 | H11: 931468624 | I11: 75204004537
A12: =ROW()-1 -> 11 | B12: 122000248 | C12: 22CT111 | D12: Lê Anh | E12: Khôi | F12: Nam | G12: 37996 | H12: 764077358 | I12: 75204008330
A13: =ROW()-1 -> 12 | B13: 122000268 | C13: 22CT111 | D13: Vũ Tiến | E13: Đức | F13: Nam | G13: 24/08/2004 | H13: 984814271 | I13: 276042253
A14: =ROW()-1 -> 13 | B14: 122000315 | C14: 22CT111 | D14: Trần Mạnh | E14: Thái | F14: Nam | G14: 17/06/2004 | H14: 868994544 | I14: 75204013148
A15: =ROW()-1 -> 14 | B15: 122000326 | C15: 22CT111 | D15: Hàn Quốc Phú | E15: Hân | F15: Nam | G15: 25/12/2004 | H15: 911176340 | I15: 45204003690
A16: =ROW()-1 -> 15 | B16: 122000336 | C16: 22CT111 | D16: Nguyễn Trần Trung | E16: Kiên | F16: Nam | G16: 19/01/2003 | H16: 888827445 | I16: 75203001146
A17: =ROW()-1 -> 16 | B17: 122000343 | C17: 22CT111 | D17: Huỳnh Minh | E17: Sang | F17: Nam | G17: 38330 | H17: 961810760 | I17: 75204003851
A18: =ROW()-1 -> 17 | B18: 122000357 | C18: 22CT111 | D18: Trần Võ Quốc | E18: Huy | F18: Nam | G18: 20/06/2004 | H18: 825493712 | I18: 75204019211
A19: =ROW()-1 -> 18 | B19: 122000385 | C19: 22CT111 | D19: Lê Nguyễn Minh | E19: Chiến | F19: Nam | G19: 38268 | H19: 982786983 | I19: 75204014281
A20: =ROW()-1 -> 19 | B20: 122000386 | C20: 22CT111 | D20: Trần Đăng | E20: Khoa | F20: Nam | G20: 15/01/2004 | H20: 914753165 | I20: 75204007239
A21: =ROW()-1 -> 20 | B21: 122000404 | C21: 22CT111 | D21: Trần Văn | E21: Hưng | F21: Nam | G21: 38025 | H21: 848180018 | I21: 75204007156
A22: =ROW()-1 -> 21 | B22: 122000455 | C22: 22CT111 | D22: Nguyễn Trường | E22: Duy | F22: Nam | G22: 27/03/2002 | H22: 372666743 | I22: 75202014852
A23: =ROW()-1 -> 22 | B23: 122000490 | C23: 22CT111 | D23: Trần Châu | E23: Quý | F23: Nam | G23: 38140 | H23: 908998503 | I23: 75204010900
A24: =ROW()-1 -> 23 | B24: 122000520 | C24: 22CT111 | D24: Phạm Gia | E24: Thoại | F24: Nam | G24: 25/01/2004 | H24: 931059840 | I24: 91204017115
A25: =ROW()-1 -> 24 | B25: 122000598 | C25: 22CT111 | D25: Phạm Nguyễn Quốc | E25: Huy | F25: Nam | G25: 25/12/2004 | H25: 364064731 | I25: 75204006039
A26: =ROW()-1 -> 25 | B26: 122000601 | C26: 22CT111 | D26: Nguyễn Tiến | E26: Trường | F26: Nam | G26: 14/08/2004 | H26: 335520911 | I26: 75204008783
A27: =ROW()-1 -> 26 | B27: 122000682 | C27: 22CT111 | D27: Nguyễn Tiến | E27: Phúc | F27: Nam | G27: 19/09/2004 | H27: 824646679 | I27: 87204019062
A28: =ROW()-1 -> 27 | B28: 122000970 | C28: 22CT111 | D28: Lê Huỳnh | E28: Phúc | F28: Nam | G28: 13/08/2004 | H28: 966186920 | I28: 272985046
A29: =ROW()-1 -> 28 | B29: 122001011 | C29: 22CT111 | D29: Lê Đức | E29: Thịnh | F29: Nam | G29: 37989 | H29: 367075722 | I29: 30204006670
A30: =ROW()-1 -> 29 | B30: 122001282 | C30: 22CT111 | D30: Phạm | E30: Dũng | F30: Nam | G30: 38211 | H30: 976541503 | I30: 75204012420
A31: =ROW()-1 -> 30 | B31: 122001350 | C31: 22CT111 | D31: Lại Xuân | E31: Quang | F31: Nam | G31: 29/11/2004 | H31: 325906617 | I31: 67204000342
A32: =ROW()-1 -> 31 | B32: 122001361 | C32: 22CT111 | D32: Nguyễn Đức | E32: Phúc | F32: Nam | G32: 25/06/2003 | H32: 961763318 | I32: 187913543
A33: =ROW()-1 -> 32 | B33: 121000156 | C33: 22CT112 | D33: Nguyễn Linh Quốc | E33: Bảo | F33: Nam | G33: 28/11/2003 | H33: 948418743 | I33: 276057510
A34: =ROW()-1 -> 33 | B34: 121001240 | C34: 22CT112 | D34: Đỗ Khắc | E34: Đức | F34: Nam | G34: 37298 | H34: 902186519 | I34: 272965950
A35: =ROW()-1 -> 34 | B35: 122000118 | C35: 22CT112 | D35: Nguyễn Khánh | E35: Tâm | F35: Nam | G35: 38111 | H35: 963296424 | I35: 75204016838
A36: =ROW()-1 -> 35 | B36: 122000163 | C36: 22CT112 | D36: Trần Gia | E36: Huy | F36: Nam | G36: 15/09/2004 | H36: 933064408 | I36: 80204010592
A37: =ROW()-1 -> 36 | B37: 122000181 | C37: 22CT112 | D37: Vũ Văn | E37: Phú | F37: Nam | G37: 19/07/2004 | H37: 865864336 | I37: 40204026723
A38: =ROW()-1 -> 37 | B38: 122000273 | C38: 22CT112 | D38: Dương Đình | E38: Đăng | F38: Nam | G38: 38240 | H38: 917693916 | I38: 75204022693
A39: =ROW()-1 -> 38 | B39: 122000331 | C39: 22CT112 | D39: Nguyễn Thế Minh | E39: Thiện | F39: Nam | G39: 22/04/2004 | H39: 369246243 | I39: 74204003284
A40: =ROW()-1 -> 39 | B40: 122000421 | C40: 22CT112 | D40: Nguyễn Sơn Phi | E40: Hoàng | F40: Nam | G40: 37989 | H40: 346980771 | I40: 75204002569
...

Sheet F_DangKiGiaoVien
A1: =IFERROR(__xludf.DUMMYFUNCTION("IMPORTRANGE(""https://docs.google.com/spreadsheets/d/1HtseJEbWZNzqg9UC7KaFWDompUG47h_TcSWC6V-BuSo/edit?resourcekey=&gid=903065054#gid=903065054"",""Form Responses 1!A:Q"")"),"Timestamp") -> Timestamp | B1: =IFERROR(__xludf.DUMMYFUNCTION("""COMPUTED_VALUE"""),"Email Address") -> Email Address | C1: =IFERROR(__xludf.DUMMYFUNCTION("""COMPUTED_VALUE"""),"MSSV") -> MSSV | D1: =IFERROR(__xludf.DUMMYFUNCTION("""COMPUTED_VALUE"""),"Họ và tên") -> Họ và tên | E1: =IFERROR(__xludf.DUMMYFUNCTION("""COMPUTED_VALUE"""),"Số điện thoại") -> Số điện thoại | F1: =IFERROR(__xludf.DUMMYFUNCTION("""COMPUTED_VALUE"""),"Lớp") -> Lớp | G1: =IFERROR(__xludf.DUMMYFUNCTION("""COMPUTED_VALUE"""),"Thuộc diện") -> Thuộc diện | H1: =IFERROR(__xludf.DUMMYFUNCTION("""COMPUTED_VALUE"""),"Giáo viên hướng dẫn") -> Giáo viên hướng dẫn | I1: =IFERROR(__xludf.DUMMYFUNCTION("""COMPUTED_VALUE"""),"Tên Giáo viên (khi chọn Giáo viên khác)") -> Tên Giáo viên (khi chọn Giáo viên khác) | J1: =IFERROR(__xludf.DUMMYFUNCTION("""COMPUTED_VALUE"""),"Tên đề tài") -> Tên đề tài | K1: =IFERROR(__xludf.DUMMYFUNCTION("""COMPUTED_VALUE"""),"Mục tiêu") -> Mục tiêu | L1: =IFERROR(__xludf.DUMMYFUNCTION("""COMPUTED_VALUE"""),"Nội dung thực hiện") -> Nội dung thực hiện | M1: =IFERROR(__xludf.DUMMYFUNCTION("""COMPUTED_VALUE"""),"Ghi chú (Nếu có)") -> Ghi chú (Nếu có) | N1: =IFERROR(__xludf.DUMMYFUNCTION("""COMPUTED_VALUE"""),"Số quyết đinh đặc cách (Nếu chưa có ghi rõ là được đặc cách do trường hợp nào)") -> Số quyết đinh đặc cách (Nếu chưa có ghi rõ là được đặc cách do trường hợp nào) | O1: =IFERROR(__xludf.DUMMYFUNCTION("""COMPUTED_VALUE"""),"Số điểm được đặc cách") -> Số điểm được đặc cách | P1: =IFERROR(__xludf.DUMMYFUNCTION("""COMPUTED_VALUE"""),"Minh chứng về việc đặc cách (Sinh viên nộp các minh chứng được đặc cách)") -> Minh chứng về việc đặc cách (Sinh viên nộp các minh chứng được đặc cách) | Q1: =IFERROR(__xludf.DUMMYFUNCTION("""COMPUTED_VALUE"""),"Đợt tốt nghiệp") -> Đợt tốt nghiệp
A2: =IFERROR(__xludf.DUMMYFUNCTION("""COMPUTED_VALUE"""),45820.40870215278) -> 45820.409 | B2: =IFERROR(__xludf.DUMMYFUNCTION("""COMPUTED_VALUE"""),"thanhdanhdnbk@gmail.com") -> thanhdanhdnbk@gmail.com | C2: =IFERROR(__xludf.DUMMYFUNCTION("""COMPUTED_VALUE"""),5.24000481E8) -> 524000481 | D2: =IFERROR(__xludf.DUMMYFUNCTION("""COMPUTED_VALUE"""),"Đặng Giang Thành Danh") -> Đặng Giang Thành Danh | E2: =IFERROR(__xludf.DUMMYFUNCTION("""COMPUTED_VALUE"""),"0815874119") -> 0815874119 | F2: =IFERROR(__xludf.DUMMYFUNCTION("""COMPUTED_VALUE"""),"24CT502") -> 24CT502 | G2: =IFERROR(__xludf.DUMMYFUNCTION("""COMPUTED_VALUE"""),"Thực hiện đồ án tốt nghiệp") -> Thực hiện đồ án tốt nghiệp | H2: =IFERROR(__xludf.DUMMYFUNCTION("""COMPUTED_VALUE"""),"Văn Đình Vỹ Phương") -> Văn Đình Vỹ Phương | J2: =IFERROR(__xludf.DUMMYFUNCTION("""COMPUTED_VALUE"""),"Nghiên cứu và triển khai mạng Mesh lai (Hybird Mesh Networks) kết hợp công nghệ có dây và không dây để nâng cao hiệu suất") -> Nghiên cứu và triển khai mạng Mesh lai (Hybird Mesh Networks) kết hợp công nghệ có dây và không dây để nâng cao hiệu suất | K2: =IFERROR(__xludf.DUMMYFUNCTION("""COMPUTED_VALUE"""),"Nâng cao hiệu suất Wifi hỗ trợ Giao viên giảng dạy và kết nối Camera trong lớp học") -> Nâng cao hiệu suất Wifi hỗ trợ Giao viên giảng dạy và kết nối Camera trong lớp học | L2: =IFERROR(__xludf.DUMMYFUNCTION("""COMPUTED_VALUE"""),"Cấu hình Router và thực hiện kết nối Mesh không dây và có dây") -> Cấu hình Router và thực hiện kết nối Mesh không dây và có dây | Q2: =IFERROR(__xludf.DUMMYFUNCTION("""COMPUTED_VALUE"""),"TNDHLTK24_20251001") -> TNDHLTK24_20251001
A3: =IFERROR(__xludf.DUMMYFUNCTION("""COMPUTED_VALUE"""),45820.41710918982) -> 45820.417 | B3: =IFERROR(__xludf.DUMMYFUNCTION("""COMPUTED_VALUE"""),"netquochai@gmail.com") -> netquochai@gmail.com | C3: =IFERROR(__xludf.DUMMYFUNCTION("""COMPUTED_VALUE"""),7.24000021E8) -> 724000021 | D3: =IFERROR(__xludf.DUMMYFUNCTION("""COMPUTED_VALUE"""),"Trần Quốc Hải") -> Trần Quốc Hải | E3: =IFERROR(__xludf.DUMMYFUNCTION("""COMPUTED_VALUE"""),"0912248361") -> 0912248361 | F3: =IFERROR(__xludf.DUMMYFUNCTION("""COMPUTED_VALUE"""),"24CT703") -> 24CT703 | G3: =IFERROR(__xludf.DUMMYFUNCTION("""COMPUTED_VALUE"""),"Thực hiện đồ án tốt nghiệp") -> Thực hiện đồ án tốt nghiệp | H3: =IFERROR(__xludf.DUMMYFUNCTION("""COMPUTED_VALUE"""),"Phan Mạnh Thường") -> Phan Mạnh Thường | J3: =IFERROR(__xludf.DUMMYFUNCTION("""COMPUTED_VALUE"""),"HỆ THỐNG QUẢN LÝ PHÒNG KHÁM") -> HỆ THỐNG QUẢN LÝ PHÒNG KHÁM | K3: =IFERROR(__xludf.DUMMYFUNCTION("""COMPUTED_VALUE"""),"Xây dựng hệ thống quản lý toàn bộ hoạt động phòng khám") -> Xây dựng hệ thống quản lý toàn bộ hoạt động phòng khám | L3: =IFERROR(__xludf.DUMMYFUNCTION("""COMPUTED_VALUE"""),"Quản lý bệnh nhân, đơn thuốc, kho dược, báo cáo, phân quyền,..") -> Quản lý bệnh nhân, đơn thuốc, kho dược, báo cáo, phân quyền,.. | Q3: =IFERROR(__xludf.DUMMYFUNCTION("""COMPUTED_VALUE"""),"TNDHLTK24_20251001") -> TNDHLTK24_20251001
A4: =IFERROR(__xludf.DUMMYFUNCTION("""COMPUTED_VALUE"""),45820.8919641088) -> 45820.892 | B4: =IFERROR(__xludf.DUMMYFUNCTION("""COMPUTED_VALUE"""),"phancham516@gmail.com") -> phancham516@gmail.com | C4: =IFERROR(__xludf.DUMMYFUNCTION("""COMPUTED_VALUE"""),7.24000038E8) -> 724000038 | D4: =IFERROR(__xludf.DUMMYFUNCTION("""COMPUTED_VALUE"""),"Phan Thị Chăm") -> Phan Thị Chăm | E4: =IFERROR(__xludf.DUMMYFUNCTION("""COMPUTED_VALUE"""),"0917206462") -> 0917206462 | F4: =IFERROR(__xludf.DUMMYFUNCTION("""COMPUTED_VALUE"""),"24CT703") -> 24CT703 | G4: =IFERROR(__xludf.DUMMYFUNCTION("""COMPUTED_VALUE"""),"Thực hiện đồ án tốt nghiệp") -> Thực hiện đồ án tốt nghiệp | H4: =IFERROR(__xludf.DUMMYFUNCTION("""COMPUTED_VALUE"""),"Phan Mạnh Thường") -> Phan Mạnh Thường | J4: =IFERROR(__xludf.DUMMYFUNCTION("""COMPUTED_VALUE"""),"ỨNG DỤNG QUẢN LÝ KINH DOANH VỀ DỊCH VỤ VIỄN THÔNG VÀ CÔNG NGHỆ THÔNG TIN CỦA VNPT") -> ỨNG DỤNG QUẢN LÝ KINH DOANH VỀ DỊCH VỤ VIỄN THÔNG VÀ CÔNG NGHỆ THÔNG TIN CỦA VNPT | K4: =IFERROR(__xludf.DUMMYFUNCTION("""COMPUTED_VALUE"""),"THIẾT KẾ 1 WEB QUẢN LÝ KINH DOANH VỀ CÁC SẢN PHẨM DV CỦA VNPT") -> THIẾT KẾ 1 WEB QUẢN LÝ KINH DOANH VỀ CÁC SẢN PHẨM DV CỦA VNPT | L4: =IFERROR(__xludf.DUMMYFUNCTION("""COMPUTED_VALUE"""),"Xây dựng hệ thống trên nền tảng web hiện đại: HTML5, CSS3, JavaScript. VÀ kết hợp với Giao diện Responsive, sử dụng thư viện Bootstrap hoặc Tailwind CSS.") -> Xây dựng hệ thống trên nền tảng web hiện đại: HTML5, CSS3, JavaScript. VÀ kết hợp với Giao diện Responsive, sử dụng thư viện Bootstrap hoặc Tailwind CSS. | Q4: =IFERROR(__xludf.DUMMYFUNCTION("""COMPUTED_VALUE"""),"TNDHLTK24_20251001") -> TNDHLTK24_20251001
A5: =IFERROR(__xludf.DUMMYFUNCTION("""COMPUTED_VALUE"""),45821.55766284722) -> 45821.558 | B5: =IFERROR(__xludf.DUMMYFUNCTION("""COMPUTED_VALUE"""),"luongthiyenthanh98@gmail.com") -> luongthiyenthanh98@gmail.com | C5: =IFERROR(__xludf.DUMMYFUNCTION("""COMPUTED_VALUE"""),7.24000023E8) -> 724000023 | D5: =IFERROR(__xludf.DUMMYFUNCTION("""COMPUTED_VALUE"""),"Lương Thị Yến Thanh") -> Lương Thị Yến Thanh | E5: =IFERROR(__xludf.DUMMYFUNCTION("""COMPUTED_VALUE"""),"0912447870") -> 0912447870 | F5: =IFERROR(__xludf.DUMMYFUNCTION("""COMPUTED_VALUE"""),"24CT702") -> 24CT702 | G5: =IFERROR(__xludf.DUMMYFUNCTION("""COMPUTED_VALUE"""),"Thực hiện đồ án tốt nghiệp") -> Thực hiện đồ án tốt nghiệp | H5: =IFERROR(__xludf.DUMMYFUNCTION("""COMPUTED_VALUE"""),"Bùi Thị Thu Trang") -> Bùi Thị Thu Trang | J5: =IFERROR(__xludf.DUMMYFUNCTION("""COMPUTED_VALUE"""),"Thiết kế giao diện website") -> Thiết kế giao diện website | K5: =IFERROR(__xludf.DUMMYFUNCTION("""COMPUTED_VALUE"""),"Thiết kế giao diện website của một công ty truyền thông") -> Thiết kế giao diện website của một công ty truyền thông | L5: =IFERROR(__xludf.DUMMYFUNCTION("""COMPUTED_VALUE"""),"Thiết kế giao diện dựa trên Figma") -> Thiết kế giao diện dựa trên Figma | Q5: =IFERROR(__xludf.DUMMYFUNCTION("""COMPUTED_VALUE"""),"TNDHLTK24_20251001") -> TNDHLTK24_20251001
A6: =IFERROR(__xludf.DUMMYFUNCTION("""COMPUTED_VALUE"""),45821.7636853588) -> 45821.764 | B6: =IFERROR(__xludf.DUMMYFUNCTION("""COMPUTED_VALUE"""),"thutrang131217@gmail.com") -> thutrang131217@gmail.com | C6: =IFERROR(__xludf.DUMMYFUNCTION("""COMPUTED_VALUE"""),7.24000016E8) -> 724000016 | D6: =IFERROR(__xludf.DUMMYFUNCTION("""COMPUTED_VALUE"""),"Nguyễn Thị Thu Trang") -> Nguyễn Thị Thu Trang | E6: =IFERROR(__xludf.DUMMYFUNCTION("""COMPUTED_VALUE"""),"0393053661") -> 0393053661 | F6: =IFERROR(__xludf.DUMMYFUNCTION("""COMPUTED_VALUE"""),"24CT702") -> 24CT702 | G6: =IFERROR(__xludf.DUMMYFUNCTION("""COMPUTED_VALUE"""),"Thực hiện đồ án tốt nghiệp") -> Thực hiện đồ án tốt nghiệp | H6: =IFERROR(__xludf.DUMMYFUNCTION("""COMPUTED_VALUE"""),"Phan Mạnh Thường") -> Phan Mạnh Thường | J6: =IFERROR(__xludf.DUMMYFUNCTION("""COMPUTED_VALUE"""),"HỆ THỐNG QUẢN LÝ NHÂN SỰ TRƯỜNG HỌC") -> HỆ THỐNG QUẢN LÝ NHÂN SỰ TRƯỜNG HỌC | K6: =IFERROR(__xludf.DUMMYFUNCTION("""COMPUTED_VALUE"""),"Quản lý tập trung thông tin nhân sự, thời gian làm việc, nghỉ phép, phân công công việc một cách nhanh chóng, hiệu quả, rõ ràng và dễ quản lý.") -> Quản lý tập trung thông tin nhân sự, thời gian làm việc, nghỉ phép, phân công công việc một cách nhanh chóng, hiệu quả, rõ ràng và dễ quản lý. | L6: =IFERROR(__xludf.DUMMYFUNCTION("""COMPUTED_VALUE"""),"PHP") -> PHP | Q6: =IFERROR(__xludf.DUMMYFUNCTION("""COMPUTED_VALUE"""),"TNDHLTK24_20251001") -> TNDHLTK24_20251001
A7: =IFERROR(__xludf.DUMMYFUNCTION("""COMPUTED_VALUE"""),45823.36342793981) -> 45823.363 | B7: =IFERROR(__xludf.DUMMYFUNCTION("""COMPUTED_VALUE"""),"vinhle11196@gmail.com") -> vinhle11196@gmail.com | C7: =IFERROR(__xludf.DUMMYFUNCTION("""COMPUTED_VALUE"""),5.24000445E8) -> 524000445 | D7: =IFERROR(__xludf.DUMMYFUNCTION("""COMPUTED_VALUE"""),"Lê Xuân Vinh") -> Lê Xuân Vinh | E7: =IFERROR(__xludf.DUMMYFUNCTION("""COMPUTED_VALUE"""),"0879466660") -> 0879466660 | F7: =IFERROR(__xludf.DUMMYFUNCTION("""COMPUTED_VALUE"""),"24CT502") -> 24CT502 | G7: =IFERROR(__xludf.DUMMYFUNCTION("""COMPUTED_VALUE"""),"Thực hiện đồ án tốt nghiệp") -> Thực hiện đồ án tốt nghiệp | H7: =IFERROR(__xludf.DUMMYFUNCTION("""COMPUTED_VALUE"""),"Hồ Ngọc Hoàng Long") -> Hồ Ngọc Hoàng Long | I7: =IFERROR(__xludf.DUMMYFUNCTION("""COMPUTED_VALUE"""),"Hồ Ngọc Hoàng Long") -> Hồ Ngọc Hoàng Long | J7: =IFERROR(__xludf.DUMMYFUNCTION("""COMPUTED_VALUE"""),"Thống kê điện năng tiêu thụ") -> Thống kê điện năng tiêu thụ | K7: =IFERROR(__xludf.DUMMYFUNCTION("""COMPUTED_VALUE"""),"Phần mềm thống kê điện năng tiêu thụ") -> Phần mềm thống kê điện năng tiêu thụ | L7: =IFERROR(__xludf.DUMMYFUNCTION("""COMPUTED_VALUE"""),"Giao diện, Cơ sở dữ liệu và chương trình thu thập dữ liệu từ thiết bị theo dõi") -> Giao diện, Cơ sở dữ liệu và chương trình thu thập dữ liệu từ thiết bị theo dõi | Q7: =IFERROR(__xludf.DUMMYFUNCTION("""COMPUTED_VALUE"""),"TNDHLTK24_20251001") -> TNDHLTK24_20251001
A8: =IFERROR(__xludf.DUMMYFUNCTION("""COMPUTED_VALUE"""),45823.6617124537) -> 45823.662 | B8: =IFERROR(__xludf.DUMMYFUNCTION("""COMPUTED_VALUE"""),"hungvy1792@gmail.com") -> hungvy1792@gmail.com | C8: =IFERROR(__xludf.DUMMYFUNCTION("""COMPUTED_VALUE"""),5.24000162E8) -> 524000162 | D8: =IFERROR(__xludf.DUMMYFUNCTION("""COMPUTED_VALUE"""),"Nguyễn Hùng Vỹ") -> Nguyễn Hùng Vỹ | E8: =IFERROR(__xludf.DUMMYFUNCTION("""COMPUTED_VALUE"""),"0522543057") -> 0522543057 | F8: =IFERROR(__xludf.DUMMYFUNCTION("""COMPUTED_VALUE"""),"24CT501") -> 24CT501 | G8: =IFERROR(__xludf.DUMMYFUNCTION("""COMPUTED_VALUE"""),"Thực hiện đồ án tốt nghiệp") -> Thực hiện đồ án tốt nghiệp | H8: =IFERROR(__xludf.DUMMYFUNCTION("""COMPUTED_VALUE"""),"Hồ Ngọc Hoàng Long") -> Hồ Ngọc Hoàng Long | I8: =IFERROR(__xludf.DUMMYFUNCTION("""COMPUTED_VALUE"""),"Hồ Ngọc Hoàng Long") -> Hồ Ngọc Hoàng Long | J8: =IFERROR(__xludf.DUMMYFUNCTION("""COMPUTED_VALUE"""),"Website sàn thương mại điện tử nông sản sạch") -> Website sàn thương mại điện tử nông sản sạch | K8: =IFERROR(__xludf.DUMMYFUNCTION("""COMPUTED_VALUE"""),"Kết nối trực tiếp nông dân với người tiêu dùng: Giảm trung gian, tăng thu nhập cho nông dân. Đảm bảo nguồn hàng rõ nguồn gốc, chất lượng. Cung cấp thực phẩm sạch, an toàn và minh bạch: Ưu tiên nông sản đạt chứng nhận VietGAP, hữu cơ. Cập nhật thông t"&"in sản phẩm minh bạch (nguồn gốc, quy trình canh tác...). Xây dựng hệ sinh thái nông nghiệp số: Ứng dụng công nghệ để số hóa hoạt động thương mại nông sản. Hỗ trợ truy xuất nguồn gốc, thanh toán online, vận chuyển tối ưu. Tạo niềm tin và thói quen tiê"&"u dùng nông sản sạch: Nâng cao nhận thức người tiêu dùng về thực phẩm sạch. Định hướng tiêu dùng bền vững và vì sức khỏe cộng đồng. Hỗ trợ phát triển nông nghiệp bền vững: Khuyến khích mô hình canh tác sạch – xanh – bền vững. Tạo sân chơi thương mại "&"lành mạnh, cạnh tranh công bằng cho các nhà cung cấp nông sản. ") -> Kết nối trực tiếp nông dân với người tiêu dùng: Giảm trung gian, tăng thu nhập cho nông dân. Đảm bảo nguồn hàng rõ nguồn gốc, chất lượng. Cung cấp thực phẩm sạch, an toàn và minh bạch: Ưu tiên nông sản đạt chứng nhận VietGAP, hữu cơ. Cập nhật thông tin sản phẩm minh bạch (nguồn gốc, quy trình canh tác...). Xây dựng hệ sinh thái nông nghiệp số: Ứng dụng công nghệ để số hóa hoạt động thương mại nông sản. Hỗ trợ truy xuất nguồn gốc, thanh toán online, vận chuyển tối ưu. Tạo niềm tin và thói quen tiêu dùng nông sản sạch: Nâng cao nhận thức người tiêu dùng về thực phẩm sạch. Định hướng tiêu dùng bền vững và vì sức khỏe cộng đồng. Hỗ trợ phát triển nông nghiệp bền vững: Khuyến khích mô hình canh tác sạch – xanh – bền vững. Tạo sân chơi thương mại lành mạnh, cạnh tranh công bằng cho các nhà cung cấp nông sản. | L8: =IFERROR(__xludf.DUMMYFUNCTION("""COMPUTED_VALUE"""),"Website cung cấp các chức năng chính như: hiển thị sản phẩm nông sản theo danh mục, tìm kiếm – lọc thông minh, giỏ hàng và đặt hàng trực tuyến, quản lý đơn hàng, thanh toán trực tuyến, thông tin nhà cung cấp, minh chứng sản phẩm chất lượng, quản lý thông "&"tin cá nhân : đơn hàng, tài khoản, thanh toán,thông báo, chức năng mở cửa hàng để buôn bán sản phẩm, chức năng admin ") -> Website cung cấp các chức năng chính như: hiển thị sản phẩm nông sản theo danh mục, tìm kiếm – lọc thông minh, giỏ hàng và đặt hàng trực tuyến, quản lý đơn hàng, thanh toán trực tuyến, thông tin nhà cung cấp, minh chứng sản phẩm chất lượng, quản lý thông tin cá nhân : đơn hàng, tài khoản, thanh toán,thông báo, chức năng mở cửa hàng để buôn bán sản phẩm, chức năng admin | Q8: =IFERROR(__xludf.DUMMYFUNCTION("""COMPUTED_VALUE"""),"TNDHLTK24_20251001") -> TNDHLTK24_20251001
A9: =IFERROR(__xludf.DUMMYFUNCTION("""COMPUTED_VALUE"""),45824.60777797454) -> 45824.608 | B9: =IFERROR(__xludf.DUMMYFUNCTION("""COMPUTED_VALUE"""),"thutram10893@gmail.com") -> thutram10893@gmail.com | C9: =IFERROR(__xludf.DUMMYFUNCTION("""COMPUTED_VALUE"""),7.24000015E8) -> 724000015 | D9: =IFERROR(__xludf.DUMMYFUNCTION("""COMPUTED_VALUE"""),"Lê Thị Thu Trâm") -> Lê Thị Thu Trâm | E9: =IFERROR(__xludf.DUMMYFUNCTION("""COMPUTED_VALUE"""),"0349855817") -> 0349855817 | F9: =IFERROR(__xludf.DUMMYFUNCTION("""COMPUTED_VALUE"""),"24CT702") -> 24CT702 | G9: =IFERROR(__xludf.DUMMYFUNCTION("""COMPUTED_VALUE"""),"Thực hiện đồ án tốt nghiệp") -> Thực hiện đồ án tốt nghiệp | H9: =IFERROR(__xludf.DUMMYFUNCTION("""COMPUTED_VALUE"""),"Phan Mạnh Thường") -> Phan Mạnh Thường | I9: =IFERROR(__xludf.DUMMYFUNCTION("""COMPUTED_VALUE"""),"Nguyễn Minh Phúc") -> Nguyễn Minh Phúc | J9: =IFERROR(__xludf.DUMMYFUNCTION("""COMPUTED_VALUE"""),"Xây dựng web về trường học") -> Xây dựng web về trường học | K9: =IFERROR(__xludf.DUMMYFUNCTION("""COMPUTED_VALUE"""),"Cho người dùng có thể thêm các thông tin của trường ") -> Cho người dùng có thể thêm các thông tin của trường | L9: =IFERROR(__xludf.DUMMYFUNCTION("""COMPUTED_VALUE"""),"Sử dụng các ngôn ngữ đã được học") -> Sử dụng các ngôn ngữ đã được học | Q9: =IFERROR(__xludf.DUMMYFUNCTION("""COMPUTED_VALUE"""),"TNDHLTK24_20251001") -> TNDHLTK24_20251001
A10: =IFERROR(__xludf.DUMMYFUNCTION("""COMPUTED_VALUE"""),45824.7328519213) -> 45824.733 | B10: =IFERROR(__xludf.DUMMYFUNCTION("""COMPUTED_VALUE"""),"man1772003@gmail.com") -> man1772003@gmail.com | C10: =IFERROR(__xludf.DUMMYFUNCTION("""COMPUTED_VALUE"""),5.24000312E8) -> 524000312 | D10: =IFERROR(__xludf.DUMMYFUNCTION("""COMPUTED_VALUE"""),"Trần Ngọc Mẫn") -> Trần Ngọc Mẫn | E10: =IFERROR(__xludf.DUMMYFUNCTION("""COMPUTED_VALUE"""),"0814528145") -> 0814528145 | F10: =IFERROR(__xludf.DUMMYFUNCTION("""COMPUTED_VALUE"""),"24CT502") -> 24CT502 | G10: =IFERROR(__xludf.DUMMYFUNCTION("""COMPUTED_VALUE"""),"Thực hiện đồ án tốt nghiệp") -> Thực hiện đồ án tốt nghiệp | H10: =IFERROR(__xludf.DUMMYFUNCTION("""COMPUTED_VALUE"""),"Lê Chân Thiện Tâm") -> Lê Chân Thiện Tâm | J10: =IFERROR(__xludf.DUMMYFUNCTION("""COMPUTED_VALUE"""),"Website giao dịch nhà ở, căn hộ") -> Website giao dịch nhà ở, căn hộ | K10: =IFERROR(__xludf.DUMMYFUNCTION("""COMPUTED_VALUE"""),"Cho phép người dùng có nhu cầu cho thuê, mua bán nhà ở, căn hộ xem các thông tin về nhà ở, căn hộ được đăng trên website, thông tin liên hệ,... Giúp tiết kiệm thời gian công sức để tìm được nhà ở phù hợp với nhu cầu hoặc đăng bán") -> Cho phép người dùng có nhu cầu cho thuê, mua bán nhà ở, căn hộ xem các thông tin về nhà ở, căn hộ được đăng trên website, thông tin liên hệ,... Giúp tiết kiệm thời gian công sức để tìm được nhà ở phù hợp với nhu cầu hoặc đăng bán | L10: =IFERROR(__xludf.DUMMYFUNCTION("""COMPUTED_VALUE"""),"Gồm trang đăng bán, hiển thị các nhà ở căn hộ, cho phép đăng bán và cho thuê,...") -> Gồm trang đăng bán, hiển thị các nhà ở căn hộ, cho phép đăng bán và cho thuê,... | Q10: =IFERROR(__xludf.DUMMYFUNCTION("""COMPUTED_VALUE"""),"TNDHLTK24_20251001") -> TNDHLTK24_20251001
A11: =IFERROR(__xludf.DUMMYFUNCTION("""COMPUTED_VALUE"""),45824.81403146991) -> 45824.814 | B11: =IFERROR(__xludf.DUMMYFUNCTION("""COMPUTED_VALUE"""),"bienhoahong2891@gmail.com") -> bienhoahong2891@gmail.com | C11: =IFERROR(__xludf.DUMMYFUNCTION("""COMPUTED_VALUE"""),7.24000022E8) -> 724000022 | D11: =IFERROR(__xludf.DUMMYFUNCTION("""COMPUTED_VALUE"""),"Nguyễn Thị Nhung") -> Nguyễn Thị Nhung | E11: =IFERROR(__xludf.DUMMYFUNCTION("""COMPUTED_VALUE"""),"0375689786") -> 0375689786 | F11: =IFERROR(__xludf.DUMMYFUNCTION("""COMPUTED_VALUE"""),"24CT702") -> 24CT702 | G11: =IFERROR(__xludf.DUMMYFUNCTION("""COMPUTED_VALUE"""),"Thực hiện đồ án tốt nghiệp") -> Thực hiện đồ án tốt nghiệp | H11: =IFERROR(__xludf.DUMMYFUNCTION("""COMPUTED_VALUE"""),"Hồ Ngọc Hoàng Long") -> Hồ Ngọc Hoàng Long | I11: =IFERROR(__xludf.DUMMYFUNCTION("""COMPUTED_VALUE"""),"Hồ Ngọc Hoàng Long") -> Hồ Ngọc Hoàng Long | J11: =IFERROR(__xludf.DUMMYFUNCTION("""COMPUTED_VALUE"""),"Quản lý sổ liên lạc điện tử") -> Quản lý sổ liên lạc điện tử | K11: =IFERROR(__xludf.DUMMYFUNCTION("""COMPUTED_VALUE"""),"Xử lý nghiệp vụ và logic hệ thống Quản lý các chức năng như: điểm số, nhận xét, lớp học, người dùng (giáo viên, phụ huynh, học sinh). Thực hiện các chức năng thêm/sửa/xóa dữ liệu một cách bảo mật và chính xác. Cung cấp API cho front-end Xây dựng các R"&"estful API phục vụ việc lấy, cập nhật, thêm mới thông tin từ frontend gửi lên. Đảm bảo an toàn và phân quyền truy cập") -> Xử lý nghiệp vụ và logic hệ thống Quản lý các chức năng như: điểm số, nhận xét, lớp học, người dùng (giáo viên, phụ huynh, học sinh). Thực hiện các chức năng thêm/sửa/xóa dữ liệu một cách bảo mật và chính xác. Cung cấp API cho front-end Xây dựng các Restful API phục vụ việc lấy, cập nhật, thêm mới thông tin từ frontend gửi lên. Đảm bảo an toàn và phân quyền truy cập | L11: =IFERROR(__xludf.DUMMYFUNCTION("""COMPUTED_VALUE"""),"Xác thực người dùng qua token (JWT) hoặc session. Phân quyền: giáo viên chỉ thấy học sinh lớp mình; phụ huynh chỉ thấy con mình. Lưu trữ và truy xuất dữ liệu hiệu quả Thiết kế và tối ưu cơ sở dữ liệu (SQL hoặc NoSQL) để truy xuất nhanh và chính xác. L"&"ưu trữ lịch sử thay đổi (nếu cần), hỗ trợ sao lưu – khôi phục dữ liệu. Xử lý thông báo Gửi email/thông báo đến phụ huynh khi có cập nhật mới từ giáo viên.") -> Xác thực người dùng qua token (JWT) hoặc session. Phân quyền: giáo viên chỉ thấy học sinh lớp mình; phụ huynh chỉ thấy con mình. Lưu trữ và truy xuất dữ liệu hiệu quả Thiết kế và tối ưu cơ sở dữ liệu (SQL hoặc NoSQL) để truy xuất nhanh và chính xác. Lưu trữ lịch sử thay đổi (nếu cần), hỗ trợ sao lưu – khôi phục dữ liệu. Xử lý thông báo Gửi email/thông báo đến phụ huynh khi có cập nhật mới từ giáo viên. | Q11: =IFERROR(__xludf.DUMMYFUNCTION("""COMPUTED_VALUE"""),"TNDHLTK24_20251001") -> TNDHLTK24_20251001
A12: =IFERROR(__xludf.DUMMYFUNCTION("""COMPUTED_VALUE"""),45824.837321643514) -> 45824.837 | B12: =IFERROR(__xludf.DUMMYFUNCTION("""COMPUTED_VALUE"""),"dongthimyven1989@gmail.com") -> dongthimyven1989@gmail.com | C12: =IFERROR(__xludf.DUMMYFUNCTION("""COMPUTED_VALUE"""),7.24000029E8) -> 724000029 | D12: =IFERROR(__xludf.DUMMYFUNCTION("""COMPUTED_VALUE"""),"Đồng Thị Mỹ Vẹn") -> Đồng Thị Mỹ Vẹn | E12: =IFERROR(__xludf.DUMMYFUNCTION("""COMPUTED_VALUE"""),"0349853869") -> 0349853869 | F12: =IFERROR(__xludf.DUMMYFUNCTION("""COMPUTED_VALUE"""),"24CT702") -> 24CT702 | G12: =IFERROR(__xludf.DUMMYFUNCTION("""COMPUTED_VALUE"""),"Thực hiện đồ án tốt nghiệp") -> Thực hiện đồ án tốt nghiệp | H12: =IFERROR(__xludf.DUMMYFUNCTION("""COMPUTED_VALUE"""),"Hồ Ngọc Hoàng Long") -> Hồ Ngọc Hoàng Long | I12: =IFERROR(__xludf.DUMMYFUNCTION("""COMPUTED_VALUE"""),"Hồ Ngọc Hoàng Long") -> Hồ Ngọc Hoàng Long | J12: =IFERROR(__xludf.DUMMYFUNCTION("""COMPUTED_VALUE"""),"Quản lý sổ liên lạc điện tử") -> Quản lý sổ liên lạc điện tử | K12: =IFERROR(__xludf.DUMMYFUNCTION("""COMPUTED_VALUE"""),"Xây dựng giao diện người dùng thân thiện, dễ sử dụng Đảm bảo người dùng như phụ huynh, giáo viên, học sinh có thể thao tác dễ dàng trên nền tảng. Hiển thị rõ ràng các chức năng: xem điểm, nhận xét, thông báo, phản hồi,... Hiển thị dữ liệu động từ hệ th"&"ống backend Gọi API để lấy danh sách học sinh, điểm số, nhận xét, thông báo,... Đáp ứng nhiều thiết bị") -> Xây dựng giao diện người dùng thân thiện, dễ sử dụng Đảm bảo người dùng như phụ huynh, giáo viên, học sinh có thể thao tác dễ dàng trên nền tảng. Hiển thị rõ ràng các chức năng: xem điểm, nhận xét, thông báo, phản hồi,... Hiển thị dữ liệu động từ hệ thống backend Gọi API để lấy danh sách học sinh, điểm số, nhận xét, thông báo,... Đáp ứng nhiều thiết bị | L12: =IFERROR(__xludf.DUMMYFUNCTION("""COMPUTED_VALUE"""),"Thiết kế responsive để hoạt động tốt trên cả máy tính, tablet và điện thoại. Cung cấp trải nghiệm tương tác tốt Hỗ trợ người dùng nhập liệu, chọn lớp học, tìm kiếm học sinh, gửi phản hồi,... Tạo hiệu ứng hiển thị như loading, toast thông báo, xác nhận "&"gửi,... ") -> Thiết kế responsive để hoạt động tốt trên cả máy tính, tablet và điện thoại. Cung cấp trải nghiệm tương tác tốt Hỗ trợ người dùng nhập liệu, chọn lớp học, tìm kiếm học sinh, gửi phản hồi,... Tạo hiệu ứng hiển thị như loading, toast thông báo, xác nhận gửi,... | Q12: =IFERROR(__xludf.DUMMYFUNCTION("""COMPUTED_VALUE"""),"TNDHLTK24_20251001") -> TNDHLTK24_20251001
A13: =IFERROR(__xludf.DUMMYFUNCTION("""COMPUTED_VALUE"""),45824.8653697338) -> 45824.865 | B13: =IFERROR(__xludf.DUMMYFUNCTION("""COMPUTED_VALUE"""),"nhut123ok@gmail.com") -> nhut123ok@gmail.com | C13: =IFERROR(__xludf.DUMMYFUNCTION("""COMPUTED_VALUE"""),5.24000189E8) -> 524000189 | D13: =IFERROR(__xludf.DUMMYFUNCTION("""COMPUTED_VALUE"""),"Phan Nguyễn Nhựt") -> Phan Nguyễn Nhựt | E13: =IFERROR(__xludf.DUMMYFUNCTION("""COMPUTED_VALUE"""),"0376679487") -> 0376679487 | F13: =IFERROR(__xludf.DUMMYFUNCTION("""COMPUTED_VALUE"""),"24CT501") -> 24CT501 | G13: =IFERROR(__xludf.DUMMYFUNCTION("""COMPUTED_VALUE"""),"Thực hiện đồ án tốt nghiệp") -> Thực hiện đồ án tốt nghiệp | H13: =IFERROR(__xludf.DUMMYFUNCTION("""COMPUTED_VALUE"""),"Hồ Ngọc Hoàng Long") -> Hồ Ngọc Hoàng Long | I13: =IFERROR(__xludf.DUMMYFUNCTION("""COMPUTED_VALUE"""),"Hồ Ngọc Hoàng Long") -> Hồ Ngọc Hoàng Long | J13: =IFERROR(__xludf.DUMMYFUNCTION("""COMPUTED_VALUE"""),"Website cho mượn và quản lý sách tại thư viện") -> Website cho mượn và quản lý sách tại thư viện | K13: =IFERROR(__xludf.DUMMYFUNCTION("""COMPUTED_VALUE"""),"Mục tiêu Số hóa quy trình mượn – trả sách truyền thống Tự động hóa việc quản lý mượn, trả và theo dõi tình trạng sách để giảm thời gian và công sức cho thủ thư. Tạo nền tảng tra cứu và mượn sách trực tuyến cho người dùng Cho phép sinh viên, giáo viên "&"dễ dàng tìm kiếm sách, xem thông tin chi tiết, và đăng ký mượn sách từ xa. Nâng cao hiệu quả quản lý sách trong thư viện Quản trị viên dễ dàng quản lý kho sách, phân loại, cập nhật tình trạng sách, kiểm tra lịch sử mượn – trả và thống kê nhanh chóng. G"&"iảm thiểu sai sót và thất thoát sách Hệ thống ghi nhận tự động lịch sử mượn – trả, nhắc hạn trả sách và hỗ trợ kiểm tra tồn kho chính xác.") -> Mục tiêu Số hóa quy trình mượn – trả sách truyền thống Tự động hóa việc quản lý mượn, trả và theo dõi tình trạng sách để giảm thời gian và công sức cho thủ thư. Tạo nền tảng tra cứu và mượn sách trực tuyến cho người dùng Cho phép sinh viên, giáo viên dễ dàng tìm kiếm sách, xem thông tin chi tiết, và đăng ký mượn sách từ xa. Nâng cao hiệu quả quản lý sách trong thư viện Quản trị viên dễ dàng quản lý kho sách, phân loại, cập nhật tình trạng sách, kiểm tra lịch sử mượn – trả và thống kê nhanh chóng. Giảm thiểu sai sót và thất thoát sách Hệ thống ghi nhận tự động lịch sử mượn – trả, nhắc hạn trả sách và hỗ trợ kiểm tra tồn kho chính xác. | L13: =IFERROR(__xludf.DUMMYFUNCTION("""COMPUTED_VALUE"""),"Xây dựng website hệ thống cho mượn và quản lý sách tại thư viện nhằm hỗ trợ thư viện số hóa quá trình quản lý sách và hoạt động mượn – trả sách của người dùng một cách hiệu quả, nhanh chóng và chính xác. Hệ thống cho phép người dùng (sinh viên, giáo viên"&"...) tra cứu sách trực tuyến, đăng ký mượn sách, theo dõi lịch sử mượn – trả và nhận thông báo khi đến hạn trả sách. Quản trị viên có thể quản lý sách, danh mục, người dùng, và thống kê số liệu mượn") -> Xây dựng website hệ thống cho mượn và quản lý sách tại thư viện nhằm hỗ trợ thư viện số hóa quá trình quản lý sách và hoạt động mượn – trả sách của người dùng một cách hiệu quả, nhanh chóng và chính xác. Hệ thống cho phép người dùng (sinh viên, giáo viên...) tra cứu sách trực tuyến, đăng ký mượn sách, theo dõi lịch sử mượn – trả và nhận thông báo khi đến hạn trả sách. Quản trị viên có thể quản lý sách, danh mục, người dùng, và thống kê số liệu mượn | Q13: =IFERROR(__xludf.DUMMYFUNCTION("""COMPUTED_VALUE"""),"TNDHLTK24_20251001") -> TNDHLTK24_20251001
A14: =IFERROR(__xludf.DUMMYFUNCTION("""COMPUTED_VALUE"""),45824.875745578705) -> 45824.876 | B14: =IFERROR(__xludf.DUMMYFUNCTION("""COMPUTED_VALUE"""),"bacphan.info@gmail.com") -> bacphan.info@gmail.com | C14: =IFERROR(__xludf.DUMMYFUNCTION("""COMPUTED_VALUE"""),5.24000166E8) -> 524000166 | D14: =IFERROR(__xludf.DUMMYFUNCTION("""COMPUTED_VALUE"""),"Phan Ngọc Phương Bắc") -> Phan Ngọc Phương Bắc | E14: =IFERROR(__xludf.DUMMYFUNCTION("""COMPUTED_VALUE"""),"0367110215") -> 0367110215 | F14: =IFERROR(__xludf.DUMMYFUNCTION("""COMPUTED_VALUE"""),"24CT501") -> 24CT501 | G14: =IFERROR(__xludf.DUMMYFUNCTION("""COMPUTED_VALUE"""),"Thực hiện đồ án tốt nghiệp") -> Thực hiện đồ án tốt nghiệp | H14: =IFERROR(__xludf.DUMMYFUNCTION("""COMPUTED_VALUE"""),"Hoàng Hải Dương") -> Hoàng Hải Dương | I14: =IFERROR(__xludf.DUMMYFUNCTION("""COMPUTED_VALUE"""),"Hoàng Hải Dương") -> Hoàng Hải Dương | J14: =IFERROR(__xludf.DUMMYFUNCTION("""COMPUTED_VALUE"""),"WebLLM Booking") -> WebLLM Booking | K14: =IFERROR(__xludf.DUMMYFUNCTION("""COMPUTED_VALUE"""),"Xây dựng hệ thống quản lý booking khách sạn tiêu chuẩn với đầy đủ chức năng, kết họp với Agent AI và MCP tạo ra WebLLM có thể trả lời yêu cầu của khách hàng và tự động đặt phòng, kết hợp với thanh toán SePay và tự Check-in bằng QrCode") -> Xây dựng hệ thống quản lý booking khách sạn tiêu chuẩn với đầy đủ chức năng, kết họp với Agent AI và MCP tạo ra WebLLM có thể trả lời yêu cầu của khách hàng và tự động đặt phòng, kết hợp với thanh toán SePay và tự Check-in bằng QrCode | L14: =IFERROR(__xludf.DUMMYFUNCTION("""COMPUTED_VALUE"""),"1. Tạo hệ thống quản lý nhân sự, tài sản, thông tin doanh nghiệp 2. Tạo hệ thống quản lý booking trực quan trên dạng lịch 3. Tạo hệ thống thống kê và biểu đồ cơ bản để thống kê dữ liệu 4. Tạo Agent AI kết hợp MCP trên nền tảng N8N (sefl host) 5. Xây dựng "&"WebLLM thực hiện các yêu cầu của khách hàng. 6. Xây hệ thống thanh toán thông qua SePay và API webhook 7. Hệ thống check-in đơn giản khi khách nhận phòng bằng QrCode") -> 1. Tạo hệ thống quản lý nhân sự, tài sản, thông tin doanh nghiệp 2. Tạo hệ thống quản lý booking trực quan trên dạng lịch 3. Tạo hệ thống thống kê và biểu đồ cơ bản để thống kê dữ liệu 4. Tạo Agent AI kết hợp MCP trên nền tảng N8N (sefl host) 5. Xây dựng WebLLM thực hiện các yêu cầu của khách hàng. 6. Xây hệ thống thanh toán thông qua SePay và API webhook 7. Hệ thống check-in đơn giản khi khách nhận phòng bằng QrCode | Q14: =IFERROR(__xludf.DUMMYFUNCTION("""COMPUTED_VALUE"""),"TNDHLTK24_20251001") -> TNDHLTK24_20251001
A15: =IFERROR(__xludf.DUMMYFUNCTION("""COMPUTED_VALUE"""),45824.91698758102) -> 45824.917 | B15: =IFERROR(__xludf.DUMMYFUNCTION("""COMPUTED_VALUE"""),"nvhuyvu@gmail.com") -> nvhuyvu@gmail.com | C15: =IFERROR(__xludf.DUMMYFUNCTION("""COMPUTED_VALUE"""),7.24000014E8) -> 724000014 | D15: =IFERROR(__xludf.DUMMYFUNCTION("""COMPUTED_VALUE"""),"Nguyễn Văn Huy Vũ") -> Nguyễn Văn Huy Vũ | E15: =IFERROR(__xludf.DUMMYFUNCTION("""COMPUTED_VALUE"""),"0978816972") -> 0978816972 | F15: =IFERROR(__xludf.DUMMYFUNCTION("""COMPUTED_VALUE"""),"24CT702") -> 24CT702 | G15: =IFERROR(__xludf.DUMMYFUNCTION("""COMPUTED_VALUE"""),"Thực hiện đồ án tốt nghiệp") -> Thực hiện đồ án tốt nghiệp | H15: =IFERROR(__xludf.DUMMYFUNCTION("""COMPUTED_VALUE"""),"Hồ Ngọc Hoàng long") -> Hồ Ngọc Hoàng long | I15: =IFERROR(__xludf.DUMMYFUNCTION("""COMPUTED_VALUE"""),"Hồ Ngọc Hoàng long") -> Hồ Ngọc Hoàng long | J15: =IFERROR(__xludf.DUMMYFUNCTION("""COMPUTED_VALUE"""),"Xây dựng website cho công ty") -> Xây dựng website cho công ty | K15: =IFERROR(__xludf.DUMMYFUNCTION("""COMPUTED_VALUE"""),"Xây dựng 1 website quảng bá thương hiệu, giới thiệu sản phẩm của công ty") -> Xây dựng 1 website quảng bá thương hiệu, giới thiệu sản phẩm của công ty | L15: =IFERROR(__xludf.DUMMYFUNCTION("""COMPUTED_VALUE"""),"Thiết kế web") -> Thiết kế web | Q15: =IFERROR(__xludf.DUMMYFUNCTION("""COMPUTED_VALUE"""),"TNDHLTK24_20251001") -> TNDHLTK24_20251001
A16: =IFERROR(__xludf.DUMMYFUNCTION("""COMPUTED_VALUE"""),45825.57254916667) -> 45825.573 | B16: =IFERROR(__xludf.DUMMYFUNCTION("""COMPUTED_VALUE"""),"xuantu041085@gmail.com") -> xuantu041085@gmail.com | C16: =IFERROR(__xludf.DUMMYFUNCTION("""COMPUTED_VALUE"""),7.24000025E8) -> 724000025 | D16: =IFERROR(__xludf.DUMMYFUNCTION("""COMPUTED_VALUE"""),"Trần Lê Xuân Tứ") -> Trần Lê Xuân Tứ | E16: =IFERROR(__xludf.DUMMYFUNCTION("""COMPUTED_VALUE"""),"0919041085") -> 0919041085 | F16: =IFERROR(__xludf.DUMMYFUNCTION("""COMPUTED_VALUE"""),"24CT702") -> 24CT702 | G16: =IFERROR(__xludf.DUMMYFUNCTION("""COMPUTED_VALUE"""),"Thực hiện đồ án tốt nghiệp") -> Thực hiện đồ án tốt nghiệp | H16: =IFERROR(__xludf.DUMMYFUNCTION("""COMPUTED_VALUE"""),"Hồ Ngọc Hoàng Long") -> Hồ Ngọc Hoàng Long | I16: =IFERROR(__xludf.DUMMYFUNCTION("""COMPUTED_VALUE"""),"Hồ Ngọc Hoàng Long") -> Hồ Ngọc Hoàng Long | J16: =IFERROR(__xludf.DUMMYFUNCTION("""COMPUTED_VALUE"""),"Xây dựng website luyện tập toán cho hs lớp 5 với hình thức trắc nghiệm") -> Xây dựng website luyện tập toán cho hs lớp 5 với hình thức trắc nghiệm | K16: =IFERROR(__xludf.DUMMYFUNCTION("""COMPUTED_VALUE"""),"Xây dựng một website đơn giản, dễ sử dụng cho học sinh lớp 5 để luyện tập các bài tập toán theo chương trình mới.") -> Xây dựng một website đơn giản, dễ sử dụng cho học sinh lớp 5 để luyện tập các bài tập toán theo chương trình mới. | L16: =IFERROR(__xludf.DUMMYFUNCTION("""COMPUTED_VALUE"""),"Phân tích hệ thống cần xây dựng gồm các chức năng: Đăng nhập/đăng ký Luyện tập theo chuyên đề Làm bài thi thử Xem kết quả Quản lý câu hỏi (dành cho quản trị viên) ") -> Phân tích hệ thống cần xây dựng gồm các chức năng: Đăng nhập/đăng ký Luyện tập theo chuyên đề Làm bài thi thử Xem kết quả Quản lý câu hỏi (dành cho quản trị viên) | Q16: =IFERROR(__xludf.DUMMYFUNCTION("""COMPUTED_VALUE"""),"TNDHLTK24_20251001") -> TNDHLTK24_20251001
A17: =IFERROR(__xludf.DUMMYFUNCTION("""COMPUTED_VALUE"""),45825.89372246528) -> 45825.894 | B17: =IFERROR(__xludf.DUMMYFUNCTION("""COMPUTED_VALUE"""),"tranquangthaibd020288@gmail.com") -> tranquangthaibd020288@gmail.com | C17: =IFERROR(__xludf.DUMMYFUNCTION("""COMPUTED_VALUE"""),4.24000031E8) -> 424000031 | D17: =IFERROR(__xludf.DUMMYFUNCTION("""COMPUTED_VALUE"""),"Trần quang thái") -> Trần quang thái | E17: =IFERROR(__xludf.DUMMYFUNCTION("""COMPUTED_VALUE"""),"0973740740") -> 0973740740 | F17: =IFERROR(__xludf.DUMMYFUNCTION("""COMPUTED_VALUE"""),"24ct401") -> 24ct401 | G17: =IFERROR(__xludf.DUMMYFUNCTION("""COMPUTED_VALUE"""),"Thực hiện đồ án tốt nghiệp") -> Thực hiện đồ án tốt nghiệp | H17: =IFERROR(__xludf.DUMMYFUNCTION("""COMPUTED_VALUE"""),"Hồ Ngọc Hoàng Long") -> Hồ Ngọc Hoàng Long | I17: =IFERROR(__xludf.DUMMYFUNCTION("""COMPUTED_VALUE"""),"Hồ Ngọc Hoàng Long") -> Hồ Ngọc Hoàng Long | J17: =IFERROR(__xludf.DUMMYFUNCTION("""COMPUTED_VALUE"""),"Web quản lý giáo dục mầm non") -> Web quản lý giáo dục mầm non | K17: =IFERROR(__xludf.DUMMYFUNCTION("""COMPUTED_VALUE"""),"Giúp hiệu trưởng quản lý tốt mục tiêu giáo dục") -> Giúp hiệu trưởng quản lý tốt mục tiêu giáo dục | L17: =IFERROR(__xludf.DUMMYFUNCTION("""COMPUTED_VALUE"""),"Quản lý nhân sự, quản lý giáo án, phối hợp với phụ huynh chăm sóc trẻ tốt hơn") -> Quản lý nhân sự, quản lý giáo án, phối hợp với phụ huynh chăm sóc trẻ tốt hơn | Q17: =IFERROR(__xludf.DUMMYFUNCTION("""COMPUTED_VALUE"""),"TNDHLTK24_20251001") -> TNDHLTK24_20251001
A18: =IFERROR(__xludf.DUMMYFUNCTION("""COMPUTED_VALUE"""),45825.89700143518) -> 45825.897 | B18: =IFERROR(__xludf.DUMMYFUNCTION("""COMPUTED_VALUE"""),"trivuong8@gmail.com") -> trivuong8@gmail.com | C18: =IFERROR(__xludf.DUMMYFUNCTION("""COMPUTED_VALUE"""),7.24000019E8) -> 724000019 | D18: =IFERROR(__xludf.DUMMYFUNCTION("""COMPUTED_VALUE"""),"Vương Tri Vương") -> Vương Tri Vương | E18: =IFERROR(__xludf.DUMMYFUNCTION("""COMPUTED_VALUE"""),"0799708188") -> 0799708188 | F18: =IFERROR(__xludf.DUMMYFUNCTION("""COMPUTED_VALUE"""),"24CT702") -> 24CT702 | G18: =IFERROR(__xludf.DUMMYFUNCTION("""COMPUTED_VALUE"""),"Thực hiện đồ án tốt nghiệp") -> Thực hiện đồ án tốt nghiệp | H18: =IFERROR(__xludf.DUMMYFUNCTION("""COMPUTED_VALUE"""),"Hồ Ngọc Hoàng Long") -> Hồ Ngọc Hoàng Long | I18: =IFERROR(__xludf.DUMMYFUNCTION("""COMPUTED_VALUE"""),"Hồ Ngọc Hoàng Long") -> Hồ Ngọc Hoàng Long | J18: =IFERROR(__xludf.DUMMYFUNCTION("""COMPUTED_VALUE"""),"Quản Lý Mầm Non") -> Quản Lý Mầm Non | K18: =IFERROR(__xludf.DUMMYFUNCTION("""COMPUTED_VALUE"""),"giúp hiệu trưởng quản lý tốt mục tiêu giáo dục") -> giúp hiệu trưởng quản lý tốt mục tiêu giáo dục | L18: =IFERROR(__xludf.DUMMYFUNCTION("""COMPUTED_VALUE"""),"quản lý nhân sự, quản lý giáo án, phối hợp với phụ huynh chăm sóc trẻ tốt hơn") -> quản lý nhân sự, quản lý giáo án, phối hợp với phụ huynh chăm sóc trẻ tốt hơn | Q18: =IFERROR(__xludf.DUMMYFUNCTION("""COMPUTED_VALUE"""),"TNDHLTK24_20251001") -> TNDHLTK24_20251001
A19: =IFERROR(__xludf.DUMMYFUNCTION("""COMPUTED_VALUE"""),45826.34293126158) -> 45826.343 | B19: =IFERROR(__xludf.DUMMYFUNCTION("""COMPUTED_VALUE"""),"mysunshinemyhuong@gmail.com") -> mysunshinemyhuong@gmail.com | C19: =IFERROR(__xludf.DUMMYFUNCTION("""COMPUTED_VALUE"""),7.2400012E8) -> 724000120 | D19: =IFERROR(__xludf.DUMMYFUNCTION("""COMPUTED_VALUE"""),"Nguyễn Thị Hương") -> Nguyễn Thị Hương | E19: =IFERROR(__xludf.DUMMYFUNCTION("""COMPUTED_VALUE"""),"0983416176") -> 0983416176 | F19: =IFERROR(__xludf.DUMMYFUNCTION("""COMPUTED_VALUE"""),"24CT702") -> 24CT702 | G19: =IFERROR(__xludf.DUMMYFUNCTION("""COMPUTED_VALUE"""),"Thực hiện đồ án tốt nghiệp") -> Thực hiện đồ án tốt nghiệp | H19: =IFERROR(__xludf.DUMMYFUNCTION("""COMPUTED_VALUE"""),"HỒ NGỌC HOÀNG LONG") -> HỒ NGỌC HOÀNG LONG | I19: =IFERROR(__xludf.DUMMYFUNCTION("""COMPUTED_VALUE"""),"HỒ NGỌC HOÀNG LONG") -> HỒ NGỌC HOÀNG LONG | J19: =IFERROR(__xludf.DUMMYFUNCTION("""COMPUTED_VALUE"""),"Website tìm kiếm và cho thuê phòng trọ") -> Website tìm kiếm và cho thuê phòng trọ | K19: =IFERROR(__xludf.DUMMYFUNCTION("""COMPUTED_VALUE"""),"Mục tiêu chính của đề tài website tìm kiếm và cho thuê phòng trọ là xây dựng một nền tảng trực tuyến hiệu quả, tiện lợi và đáng tin cậy, giúp kết nối người có nhu cầu thuê phòng với các chủ trọ, đồng thời giải quyết những khó khăn hiện tại trong quá trình"&" tìm kiếm và quản lý thông tin phòng trọ") -> Mục tiêu chính của đề tài website tìm kiếm và cho thuê phòng trọ là xây dựng một nền tảng trực tuyến hiệu quả, tiện lợi và đáng tin cậy, giúp kết nối người có nhu cầu thuê phòng với các chủ trọ, đồng thời giải quyết những khó khăn hiện tại trong quá trình tìm kiếm và quản lý thông tin phòng trọ | L19: =IFERROR(__xludf.DUMMYFUNCTION("""COMPUTED_VALUE"""),"Xây dựng giao diện trực quan dễ dàng sử dụng thân thiện với người dùng, chức năng tìm kiếm tích hợp, quản lý bài đăng, nạp tiền vào tài khoản, đăng tin mới") -> Xây dựng giao diện trực quan dễ dàng sử dụng thân thiện với người dùng, chức năng tìm kiếm tích hợp, quản lý bài đăng, nạp tiền vào tài khoản, đăng tin mới | Q19: =IFERROR(__xludf.DUMMYFUNCTION("""COMPUTED_VALUE"""),"TNDHLTK24_20251001") -> TNDHLTK24_20251001
A20: =IFERROR(__xludf.DUMMYFUNCTION("""COMPUTED_VALUE"""),45826.34358984954) -> 45826.344 | B20: =IFERROR(__xludf.DUMMYFUNCTION("""COMPUTED_VALUE"""),"diary0101@gmail.com") -> diary0101@gmail.com | C20: =IFERROR(__xludf.DUMMYFUNCTION("""COMPUTED_VALUE"""),5.24000325E8) -> 524000325 | D20: =IFERROR(__xludf.DUMMYFUNCTION("""COMPUTED_VALUE"""),"Tạ Thị Phượng") -> Tạ Thị Phượng | E20: =IFERROR(__xludf.DUMMYFUNCTION("""COMPUTED_VALUE"""),"0982928380") -> 0982928380 | F20: =IFERROR(__xludf.DUMMYFUNCTION("""COMPUTED_VALUE"""),"24CT502") -> 24CT502 | G20: =IFERROR(__xludf.DUMMYFUNCTION("""COMPUTED_VALUE"""),"Thực hiện đồ án tốt nghiệp") -> Thực hiện đồ án tốt nghiệp | H20: =IFERROR(__xludf.DUMMYFUNCTION("""COMPUTED_VALUE"""),"Hồ Ngọc Hoàng Long") -> Hồ Ngọc Hoàng Long | I20: =IFERROR(__xludf.DUMMYFUNCTION("""COMPUTED_VALUE"""),"Hồ Ngọc Hoàng Long") -> Hồ Ngọc Hoàng Long | J20: =IFERROR(__xludf.DUMMYFUNCTION("""COMPUTED_VALUE"""),"Website tìm kiếm và cho thuê phòng trọ") -> Website tìm kiếm và cho thuê phòng trọ | K20: =IFERROR(__xludf.DUMMYFUNCTION("""COMPUTED_VALUE"""),"Mục tiêu chính của đề tài website tìm kiếm và cho thuê phòng trọ là xây dựng một nền tảng trực tuyến hiệu quả, tiện lợi và đáng tin cậy, giúp kết nối người có nhu cầu thuê phòng với các chủ trọ, đồng thời giải quyết những khó khăn hiện tại trong quá trình"&" tìm kiếm và quản lý thông tin phòng trọ") -> Mục tiêu chính của đề tài website tìm kiếm và cho thuê phòng trọ là xây dựng một nền tảng trực tuyến hiệu quả, tiện lợi và đáng tin cậy, giúp kết nối người có nhu cầu thuê phòng với các chủ trọ, đồng thời giải quyết những khó khăn hiện tại trong quá trình tìm kiếm và quản lý thông tin phòng trọ | L20: =IFERROR(__xludf.DUMMYFUNCTION("""COMPUTED_VALUE"""),"Nội dung thực hiện : Xây dựng giao diện trực quan dễ dàng sử dụng thân thiện với người dùng, chức năng tìm kiếm tích hợp, quản lý bài đăng, nạp tiền vào tài khoản, đăng tin mới ") -> Nội dung thực hiện : Xây dựng giao diện trực quan dễ dàng sử dụng thân thiện với người dùng, chức năng tìm kiếm tích hợp, quản lý bài đăng, nạp tiền vào tài khoản, đăng tin mới | Q20: =IFERROR(__xludf.DUMMYFUNCTION("""COMPUTED_VALUE"""),"TNDHLTK24_20251001") -> TNDHLTK24_20251001
A21: =IFERROR(__xludf.DUMMYFUNCTION("""COMPUTED_VALUE"""),45826.572306064816) -> 45826.572 | B21: =IFERROR(__xludf.DUMMYFUNCTION("""COMPUTED_VALUE"""),"mtquang180695@gmail.com") -> mtquang180695@gmail.com | C21: =IFERROR(__xludf.DUMMYFUNCTION("""COMPUTED_VALUE"""),5.24000175E8) -> 524000175 | D21: =IFERROR(__xludf.DUMMYFUNCTION("""COMPUTED_VALUE"""),"Mai Thanh Quang") -> Mai Thanh Quang | E21: =IFERROR(__xludf.DUMMYFUNCTION("""COMPUTED_VALUE"""),"0908150738") -> 0908150738 | F21: =IFERROR(__xludf.DUMMYFUNCTION("""COMPUTED_VALUE"""),"24CT501") -> 24CT501 | G21: =IFERROR(__xludf.DUMMYFUNCTION("""COMPUTED_VALUE"""),"Thực hiện đồ án tốt nghiệp") -> Thực hiện đồ án tốt nghiệp | H21: =IFERROR(__xludf.DUMMYFUNCTION("""COMPUTED_VALUE"""),"Nguyễn Vũ Duy Quang") -> Nguyễn Vũ Duy Quang | J21: =IFERROR(__xludf.DUMMYFUNCTION("""COMPUTED_VALUE"""),"Xây dựng mô hình HA và chiến lược sao lưu dữ liệu hiện đại cho hệ thống doanh nghiệp năm 2025") -> Xây dựng mô hình HA và chiến lược sao lưu dữ liệu hiện đại cho hệ thống doanh nghiệp năm 2025 | K21: =IFERROR(__xludf.DUMMYFUNCTION("""COMPUTED_VALUE"""),"Đề tài hướng tới việc xây dựng một hệ thống thực tiễn giúp doanh nghiệp đảm bảo: - Tính sẵn sàng cao (High Availability - HA) (bao gồm cả Network & System) - An toàn dữ liệu, giảm thiểu tối đa thiệt hại khi hỏng hóc thiết bị hoặc bị tấn công mã độc - Ứng "&"dụng các công nghệ tiên tiến") -> Đề tài hướng tới việc xây dựng một hệ thống thực tiễn giúp doanh nghiệp đảm bảo: - Tính sẵn sàng cao (High Availability - HA) (bao gồm cả Network & System) - An toàn dữ liệu, giảm thiểu tối đa thiệt hại khi hỏng hóc thiết bị hoặc bị tấn công mã độc - Ứng dụng các công nghệ tiên tiến | L21: =IFERROR(__xludf.DUMMYFUNCTION("""COMPUTED_VALUE"""),"- Khảo sát và phân tích - Thiết kế mô hình hệ thống - Triển khai thử nghiệm - Kiểm thử và đánh giá - Kết luận và đề xuất hoàn thiện") -> - Khảo sát và phân tích - Thiết kế mô hình hệ thống - Triển khai thử nghiệm - Kiểm thử và đánh giá - Kết luận và đề xuất hoàn thiện | Q21: =IFERROR(__xludf.DUMMYFUNCTION("""COMPUTED_VALUE"""),"TNDHLTK24_20251001") -> TNDHLTK24_20251001
A22: =IFERROR(__xludf.DUMMYFUNCTION("""COMPUTED_VALUE"""),45826.783940381945) -> 45826.784 | B22: =IFERROR(__xludf.DUMMYFUNCTION("""COMPUTED_VALUE"""),"tanbtu05@gmail.com") -> tanbtu05@gmail.com | C22: =IFERROR(__xludf.DUMMYFUNCTION("""COMPUTED_VALUE"""),7.2400002E8) -> 724000020 | D22: =IFERROR(__xludf.DUMMYFUNCTION("""COMPUTED_VALUE"""),"Nguyễn Văn Tấn ") -> Nguyễn Văn Tấn | E22: =IFERROR(__xludf.DUMMYFUNCTION("""COMPUTED_VALUE"""),"0862547521") -> 0862547521 | F22: =IFERROR(__xludf.DUMMYFUNCTION("""COMPUTED_VALUE"""),"24CT702") -> 24CT702 | G22: =IFERROR(__xludf.DUMMYFUNCTION("""COMPUTED_VALUE"""),"Thực hiện đồ án tốt nghiệp") -> Thực hiện đồ án tốt nghiệp | H22: =IFERROR(__xludf.DUMMYFUNCTION("""COMPUTED_VALUE"""),"Hồ Ngọc Hoàng Long") -> Hồ Ngọc Hoàng Long | I22: =IFERROR(__xludf.DUMMYFUNCTION("""COMPUTED_VALUE"""),"Hồ Ngọc Hoàng Long") -> Hồ Ngọc Hoàng Long | J22: =IFERROR(__xludf.DUMMYFUNCTION("""COMPUTED_VALUE"""),"Xây dựng website luyện tập toán cho hs lớp 5 với hình thức trắc nghiệm") -> Xây dựng website luyện tập toán cho hs lớp 5 với hình thức trắc nghiệm | K22: =IFERROR(__xludf.DUMMYFUNCTION("""COMPUTED_VALUE"""),"Xây dựng một website đơn giản, dễ sử dụng cho học sinh lớp 5 để luyện tập các bài tập toán theo chương trình mới.") -> Xây dựng một website đơn giản, dễ sử dụng cho học sinh lớp 5 để luyện tập các bài tập toán theo chương trình mới. | L22: =IFERROR(__xludf.DUMMYFUNCTION("""COMPUTED_VALUE"""),"Luyện tập theo chuyên đề Làm bài thi thử Xem kết quả Quản lý câu hỏi (dành cho quản trị viên)") -> Luyện tập theo chuyên đề Làm bài thi thử Xem kết quả Quản lý câu hỏi (dành cho quản trị viên) | Q22: =IFERROR(__xludf.DUMMYFUNCTION("""COMPUTED_VALUE"""),"TNDHLTK24_20251001") -> TNDHLTK24_20251001
A23: =IFERROR(__xludf.DUMMYFUNCTION("""COMPUTED_VALUE"""),45828.820400219905) -> 45828.82 | B23: =IFERROR(__xludf.DUMMYFUNCTION("""COMPUTED_VALUE"""),"trantrungho71@gmail.com") -> trantrungho71@gmail.com | C23: =IFERROR(__xludf.DUMMYFUNCTION("""COMPUTED_VALUE"""),5.24000322E8) -> 524000322 | D23: =IFERROR(__xludf.DUMMYFUNCTION("""COMPUTED_VALUE"""),"Nguyễn Anh Trí") -> Nguyễn Anh Trí | E23: =IFERROR(__xludf.DUMMYFUNCTION("""COMPUTED_VALUE"""),"0359071715") -> 0359071715 | F23: =IFERROR(__xludf.DUMMYFUNCTION("""COMPUTED_VALUE"""),"24CT502") -> 24CT502 | G23: =IFERROR(__xludf.DUMMYFUNCTION("""COMPUTED_VALUE"""),"Thực hiện đồ án tốt nghiệp") -> Thực hiện đồ án tốt nghiệp | H23: =IFERROR(__xludf.DUMMYFUNCTION("""COMPUTED_VALUE"""),"Hoàng Hải Dương") -> Hoàng Hải Dương | I23: =IFERROR(__xludf.DUMMYFUNCTION("""COMPUTED_VALUE"""),"Hoàng Hải Dương") -> Hoàng Hải Dương | J23: =IFERROR(__xludf.DUMMYFUNCTION("""COMPUTED_VALUE"""),"Tạo trò chơi trên nền tảng Warcraft III: Reforged") -> Tạo trò chơi trên nền tảng Warcraft III: Reforged | K23: =IFERROR(__xludf.DUMMYFUNCTION("""COMPUTED_VALUE"""),"Thiết kế trò chơi thuộc thể loại Dungeon Crawler dựa trên nền tảng của Warcraft III: Reforged") -> Thiết kế trò chơi thuộc thể loại Dungeon Crawler dựa trên nền tảng của Warcraft III: Reforged | L23: =IFERROR(__xludf.DUMMYFUNCTION("""COMPUTED_VALUE"""),"Phân tích và xác định cơ chế lối chơi của thể loại Dungeon Crawler, Viết mã để xây dựng các chức năng của trò chơi cũng như kiểm thử và chỉnh sửa lỗi trong quá trình phát triển") -> Phân tích và xác định cơ chế lối chơi của thể loại Dungeon Crawler, Viết mã để xây dựng các chức năng của trò chơi cũng như kiểm thử và chỉnh sửa lỗi trong quá trình phát triển | Q23: =IFERROR(__xludf.DUMMYFUNCTION("""COMPUTED_VALUE"""),"TNDHLTK24_20251001") -> TNDHLTK24_20251001
A24: =IFERROR(__xludf.DUMMYFUNCTION("""COMPUTED_VALUE"""),45829.44940013889) -> 45829.449 | B24: =IFERROR(__xludf.DUMMYFUNCTION("""COMPUTED_VALUE"""),"hoangvu2577@gmail.com") -> hoangvu2577@gmail.com | C24: =IFERROR(__xludf.DUMMYFUNCTION("""COMPUTED_VALUE"""),7.2400003E8) -> 724000030 | D24: =IFERROR(__xludf.DUMMYFUNCTION("""COMPUTED_VALUE"""),"LÊ ĐÌNH HOÀNG VŨ") -> LÊ ĐÌNH HOÀNG VŨ | E24: =IFERROR(__xludf.DUMMYFUNCTION("""COMPUTED_VALUE"""),"0961458243") -> 0961458243 | F24: =IFERROR(__xludf.DUMMYFUNCTION("""COMPUTED_VALUE"""),"24CT702") -> 24CT702 | G24: =IFERROR(__xludf.DUMMYFUNCTION("""COMPUTED_VALUE"""),"Thực hiện đồ án tốt nghiệp") -> Thực hiện đồ án tốt nghiệp | H24: =IFERROR(__xludf.DUMMYFUNCTION("""COMPUTED_VALUE"""),"Bùi Thị Thu Trang") -> Bùi Thị Thu Trang | J24: =IFERROR(__xludf.DUMMYFUNCTION("""COMPUTED_VALUE"""),"Thiết kế giao diện công ty truyền thông") -> Thiết kế giao diện công ty truyền thông | K24: =IFERROR(__xludf.DUMMYFUNCTION("""COMPUTED_VALUE"""),"Thiết kế giao diện công ty truyền thông") -> Thiết kế giao diện công ty truyền thông | L24: =IFERROR(__xludf.DUMMYFUNCTION("""COMPUTED_VALUE"""),"Sử dụng phần mềm figma để thực hiện") -> Sử dụng phần mềm figma để thực hiện | Q24: =IFERROR(__xludf.DUMMYFUNCTION("""COMPUTED_VALUE"""),"TNDHLTK24_20251001") -> TNDHLTK24_20251001
A25: =IFERROR(__xludf.DUMMYFUNCTION("""COMPUTED_VALUE"""),45830.85527302083) -> 45830.855 | B25: =IFERROR(__xludf.DUMMYFUNCTION("""COMPUTED_VALUE"""),"ap20192807@gmail.com") -> ap20192807@gmail.com | C25: =IFERROR(__xludf.DUMMYFUNCTION("""COMPUTED_VALUE"""),5.24000187E8) -> 524000187 | D25: =IFERROR(__xludf.DUMMYFUNCTION("""COMPUTED_VALUE"""),"Phạm Văn Anh") -> Phạm Văn Anh | E25: =IFERROR(__xludf.DUMMYFUNCTION("""COMPUTED_VALUE"""),"0827366999") -> 0827366999 | F25: =IFERROR(__xludf.DUMMYFUNCTION("""COMPUTED_VALUE"""),"24CT501") -> 24CT501 | G25: =IFERROR(__xludf.DUMMYFUNCTION("""COMPUTED_VALUE"""),"Thực hiện đồ án tốt nghiệp") -> Thực hiện đồ án tốt nghiệp | H25: =IFERROR(__xludf.DUMMYFUNCTION("""COMPUTED_VALUE"""),"Hồ Ngọc Hoàng Long") -> Hồ Ngọc Hoàng Long | I25: =IFERROR(__xludf.DUMMYFUNCTION("""COMPUTED_VALUE"""),"Hồ Ngọc Hoàng Long") -> Hồ Ngọc Hoàng Long | J25: =IFERROR(__xludf.DUMMYFUNCTION("""COMPUTED_VALUE"""),"Xây dựng website Cổng thông tin Phòng GD14- KBNN KV XV") -> Xây dựng website Cổng thông tin Phòng GD14- KBNN KV XV | K25: =IFERROR(__xludf.DUMMYFUNCTION("""COMPUTED_VALUE"""),"Giới thiếu về cơ quan và các hoạt động nghiệp vụ của cơ quan") -> Giới thiếu về cơ quan và các hoạt động nghiệp vụ của cơ quan | L25: =IFERROR(__xludf.DUMMYFUNCTION("""COMPUTED_VALUE"""),"xây dựng trang web giới thiệu cơ quan và các hoạt động nghiệp vụ, thông báo về các hoạt động của cơ quan") -> xây dựng trang web giới thiệu cơ quan và các hoạt động nghiệp vụ, thông báo về các hoạt động của cơ quan | Q25: =IFERROR(__xludf.DUMMYFUNCTION("""COMPUTED_VALUE"""),"TNDHLTK24_20251001") -> TNDHLTK24_20251001
A26: =IFERROR(__xludf.DUMMYFUNCTION("""COMPUTED_VALUE"""),45838.464727812505) -> 45838.465 | B26: =IFERROR(__xludf.DUMMYFUNCTION("""COMPUTED_VALUE"""),"kn360814@gmail.com") -> kn360814@gmail.com | C26: =IFERROR(__xludf.DUMMYFUNCTION("""COMPUTED_VALUE"""),1.21000776E8) -> 121000776 | D26: =IFERROR(__xludf.DUMMYFUNCTION("""COMPUTED_VALUE"""),"Nguyễn Hoàng Phúc Khang") -> Nguyễn Hoàng Phúc Khang | E26: =IFERROR(__xludf.DUMMYFUNCTION("""COMPUTED_VALUE"""),"0398021167") -> 0398021167 | F26: =IFERROR(__xludf.DUMMYFUNCTION("""COMPUTED_VALUE"""),"21CT114") -> 21CT114 | G26: =IFERROR(__xludf.DUMMYFUNCTION("""COMPUTED_VALUE"""),"Thực hiện đồ án tốt nghiệp") -> Thực hiện đồ án tốt nghiệp | H26: =IFERROR(__xludf.DUMMYFUNCTION("""COMPUTED_VALUE"""),"Phan Mạnh Thường") -> Phan Mạnh Thường | J26: =IFERROR(__xludf.DUMMYFUNCTION("""COMPUTED_VALUE"""),"Xây dựng Web quản lý nhân sự") -> Xây dựng Web quản lý nhân sự | K26: =IFERROR(__xludf.DUMMYFUNCTION("""COMPUTED_VALUE"""),"Có trong thuyết minh") -> Có trong thuyết minh | L26: =IFERROR(__xludf.DUMMYFUNCTION("""COMPUTED_VALUE"""),"Có trong thuyết minh") -> Có trong thuyết minh | Q26: =IFERROR(__xludf.DUMMYFUNCTION("""COMPUTED_VALUE"""),"TNDHLTK24_20251001") -> TNDHLTK24_20251001
A27: =IFERROR(__xludf.DUMMYFUNCTION("""COMPUTED_VALUE"""),45838.484778819446) -> 45838.485 | B27: =IFERROR(__xludf.DUMMYFUNCTION("""COMPUTED_VALUE"""),"tamthiletran@gmail.com") -> tamthiletran@gmail.com | C27: =IFERROR(__xludf.DUMMYFUNCTION("""COMPUTED_VALUE"""),5.24000184E8) -> 524000184 | D27: =IFERROR(__xludf.DUMMYFUNCTION("""COMPUTED_VALUE"""),"Lê Trần Tâm Thi") -> Lê Trần Tâm Thi | E27: =IFERROR(__xludf.DUMMYFUNCTION("""COMPUTED_VALUE"""),9.1752597E8) -> 917525970 | F27: =IFERROR(__xludf.DUMMYFUNCTION("""COMPUTED_VALUE"""),"24CT501") -> 24CT501 | G27: =IFERROR(__xludf.DUMMYFUNCTION("""COMPUTED_VALUE"""),"Thực hiện đồ án tốt nghiệp") -> Thực hiện đồ án tốt nghiệp | H27: =IFERROR(__xludf.DUMMYFUNCTION("""COMPUTED_VALUE"""),"Phan Mạnh Thường") -> Phan Mạnh Thường | J27: =IFERROR(__xludf.DUMMYFUNCTION("""COMPUTED_VALUE"""),"Xây dựng Website bán thời trang eco") -> Xây dựng Website bán thời trang eco | K27: =IFERROR(__xludf.DUMMYFUNCTION("""COMPUTED_VALUE"""),"Xây dựng website kinh doanh, tối ưu SEO") -> Xây dựng website kinh doanh, tối ưu SEO | L27: =IFERROR(__xludf.DUMMYFUNCTION("""COMPUTED_VALUE"""),"Xây dựng website kinh doanh, tối ưu SEO") -> Xây dựng website kinh doanh, tối ưu SEO | Q27: =IFERROR(__xludf.DUMMYFUNCTION("""COMPUTED_VALUE"""),"TNDHLTK24_20251001") -> TNDHLTK24_20251001
A28: =IFERROR(__xludf.DUMMYFUNCTION("""COMPUTED_VALUE"""),45838.6449171412) -> 45838.645 | B28: =IFERROR(__xludf.DUMMYFUNCTION("""COMPUTED_VALUE"""),"nxak1505@gmail.com") -> nxak1505@gmail.com | C28: =IFERROR(__xludf.DUMMYFUNCTION("""COMPUTED_VALUE"""),4.24000052E8) -> 424000052 | D28: =IFERROR(__xludf.DUMMYFUNCTION("""COMPUTED_VALUE"""),"Nguyễn Xuân Anh Kiệt") -> Nguyễn Xuân Anh Kiệt | E28: =IFERROR(__xludf.DUMMYFUNCTION("""COMPUTED_VALUE"""),"0794757515") -> 0794757515 | F28: =IFERROR(__xludf.DUMMYFUNCTION("""COMPUTED_VALUE"""),"24CT402") -> 24CT402 | G28: =IFERROR(__xludf.DUMMYFUNCTION("""COMPUTED_VALUE"""),"Thực hiện đồ án tốt nghiệp") -> Thực hiện đồ án tốt nghiệp | H28: =IFERROR(__xludf.DUMMYFUNCTION("""COMPUTED_VALUE"""),"Hoàng Hải Dương") -> Hoàng Hải Dương | I28: =IFERROR(__xludf.DUMMYFUNCTION("""COMPUTED_VALUE"""),"Hoàng Hải Dương") -> Hoàng Hải Dương | J28: =IFERROR(__xludf.DUMMYFUNCTION("""COMPUTED_VALUE"""),"Ứng dụng web bán thiết bị công nghệ") -> Ứng dụng web bán thiết bị công nghệ | K28: =IFERROR(__xludf.DUMMYFUNCTION("""COMPUTED_VALUE"""),"Hoàn thiện ứng dụng web giống với các trang bán lẻ sản phẩm công nghệ") -> Hoàn thiện ứng dụng web giống với các trang bán lẻ sản phẩm công nghệ | L28: =IFERROR(__xludf.DUMMYFUNCTION("""COMPUTED_VALUE"""),"xây dựng backend và frontend cho trang web để trang web có giao diện đẹp mắt và tốc độ cao cùng với khả năng xử lý thông tin và gọi api nhanh chóng") -> xây dựng backend và frontend cho trang web để trang web có giao diện đẹp mắt và tốc độ cao cùng với khả năng xử lý thông tin và gọi api nhanh chóng | Q28: =IFERROR(__xludf.DUMMYFUNCTION("""COMPUTED_VALUE"""),"TNDHLTK24_20251001") -> TNDHLTK24_20251001
A29: =IFERROR(__xludf.DUMMYFUNCTION("""COMPUTED_VALUE"""),45838.65407217592) -> 45838.654 | B29: =IFERROR(__xludf.DUMMYFUNCTION("""COMPUTED_VALUE"""),"nhatvip23456@gmail.com") -> nhatvip23456@gmail.com | C29: =IFERROR(__xludf.DUMMYFUNCTION("""COMPUTED_VALUE"""),4.24000051E8) -> 424000051 | D29: =IFERROR(__xludf.DUMMYFUNCTION("""COMPUTED_VALUE"""),"Nguyễn Nhật Anh") -> Nguyễn Nhật Anh | E29: =IFERROR(__xludf.DUMMYFUNCTION("""COMPUTED_VALUE"""),"0813121270") -> 0813121270 | F29: =IFERROR(__xludf.DUMMYFUNCTION("""COMPUTED_VALUE"""),"24CT402") -> 24CT402 | G29: =IFERROR(__xludf.DUMMYFUNCTION("""COMPUTED_VALUE"""),"Thực hiện đồ án tốt nghiệp") -> Thực hiện đồ án tốt nghiệp | H29: =IFERROR(__xludf.DUMMYFUNCTION("""COMPUTED_VALUE"""),"Hoàng Hải Dương") -> Hoàng Hải Dương | I29: =IFERROR(__xludf.DUMMYFUNCTION("""COMPUTED_VALUE"""),"Hoàng Hải Dương") -> Hoàng Hải Dương | J29: =IFERROR(__xludf.DUMMYFUNCTION("""COMPUTED_VALUE"""),"ứng dụng web bán thiết bị công nghệ") -> ứng dụng web bán thiết bị công nghệ | K29: =IFERROR(__xludf.DUMMYFUNCTION("""COMPUTED_VALUE"""),"hoàn thiện ứng dụng web với đầy đủ chức năng cần thiết giống với các trang web bán lẻ sản phẩm công nghệ ") -> hoàn thiện ứng dụng web với đầy đủ chức năng cần thiết giống với các trang web bán lẻ sản phẩm công nghệ | L29: =IFERROR(__xludf.DUMMYFUNCTION("""COMPUTED_VALUE"""),"xây dựng backend và frontend cho trang web để trang web có giao diện đẹp mắt và tốc độ cao cùng với khả năng xử lý thông tin và gọi API nhanh chóng") -> xây dựng backend và frontend cho trang web để trang web có giao diện đẹp mắt và tốc độ cao cùng với khả năng xử lý thông tin và gọi API nhanh chóng | Q29: =IFERROR(__xludf.DUMMYFUNCTION("""COMPUTED_VALUE"""),"TNDHLTK24_20251001") -> TNDHLTK24_20251001
